Workbook

Sheet Lead_Data
A1: Lead ID | B1: Signup Date | C1: Owner | D1: Contact Stage | E1: First Shipment Booked Date | F1: Marketing Lead Source | G1: Monthly Order Volume | H1: Convert Flag | I1: Owner Team | J1: Handoff Check
A2: Lead_001 | B2: 46207.58 | C2: FILT_E | D2: Follow Up | F2: Google Paid | G2: 1-100 | H2: =IF(OR(E2<>"",D2="Verified", D2="Service Done"),1,0) -> 0 | I2: =_xlfn.XLOOKUP(C2,Team_Legend!A:A,Team_Legend!B:B,"",0) -> Filteration | J2: =IF(H2=1,IF(I2="Sales","OK","Converted - Owner not Sales"),"")
A3: Lead_002 | B3: 46192.37 | C3: FILT_G | D3: Not Eligible Yet | F3: Facebook | G3: 1-100 | H3: =IF(OR(E3<>"",D3="Verified", D3="Service Done"),1,0) -> 0 | I3: =_xlfn.XLOOKUP(C3,Team_Legend!A:A,Team_Legend!B:B,"",0) -> Filteration | J3: =IF(H3=1,IF(I3="Sales","OK","Converted - Owner not Sales"),"")
A4: Lead_003 | B4: 46203.958 | C4: FILT_F | D4: Uncontactable | F4: Google Paid | G4: Just starting out | H4: =IF(OR(E4<>"",D4="Verified", D4="Service Done"),1,0) -> 0 | I4: =_xlfn.XLOOKUP(C4,Team_Legend!A:A,Team_Legend!B:B,"",0) -> Filteration | J4: =IF(H4=1,IF(I4="Sales","OK","Converted - Owner not Sales"),"")
A5: Lead_004 | B5: 46202.404 | C5: FILT_C | D5: Document & Details Pending | F5: Organic | G5: 100-300 | H5: =IF(OR(E5<>"",D5="Verified", D5="Service Done"),1,0) -> 0 | I5: =_xlfn.XLOOKUP(C5,Team_Legend!A:A,Team_Legend!B:B,"",0) -> Filteration | J5: =IF(H5=1,IF(I5="Sales","OK","Converted - Owner not Sales"),"")
A6: Lead_005 | B6: 46208.58 | C6: FILT_G | D6: Not Connected | F6: App | G6: 100-300 | H6: =IF(OR(E6<>"",D6="Verified", D6="Service Done"),1,0) -> 0 | I6: =_xlfn.XLOOKUP(C6,Team_Legend!A:A,Team_Legend!B:B,"",0) -> Filteration | J6: =IF(H6=1,IF(I6="Sales","OK","Converted - Owner not Sales"),"")
A7: Lead_006 | B7: 46198.813 | C7: FILT_A | D7: Follow-up in Future | F7: Google Paid | G7: 300-500 | H7: =IF(OR(E7<>"",D7="Verified", D7="Service Done"),1,0) -> 0 | I7: =_xlfn.XLOOKUP(C7,Team_Legend!A:A,Team_Legend!B:B,"",0) -> Filteration | J7: =IF(H7=1,IF(I7="Sales","OK","Converted - Owner not Sales"),"")
A8: Lead_007 | B8: 46207.521 | C8: FILT_A | D8: Uncontactable | F8: Google Paid | G8: 1-100 | H8: =IF(OR(E8<>"",D8="Verified", D8="Service Done"),1,0) -> 0 | I8: =_xlfn.XLOOKUP(C8,Team_Legend!A:A,Team_Legend!B:B,"",0) -> Filteration | J8: =IF(H8=1,IF(I8="Sales","OK","Converted - Owner not Sales"),"")
A9: Lead_008 | B9: 46193.494 | C9: FILT_D | D9: Junk | F9: App | G9: 1-100 | H9: =IF(OR(E9<>"",D9="Verified", D9="Service Done"),1,0) -> 0 | I9: =_xlfn.XLOOKUP(C9,Team_Legend!A:A,Team_Legend!B:B,"",0) -> Filteration | J9: =IF(H9=1,IF(I9="Sales","OK","Converted - Owner not Sales"),"")
A10: Lead_009 | B10: 46206.771 | C10: FILT_D | D10: Follow Up | F10: Organic | G10: Just starting out | H10: =IF(OR(E10<>"",D10="Verified", D10="Service Done"),1,0) -> 0 | I10: =_xlfn.XLOOKUP(C10,Team_Legend!A:A,Team_Legend!B:B,"",0) -> Filteration | J10: =IF(H10=1,IF(I10="Sales","OK","Converted - Owner not Sales"),"")
A11: Lead_010 | B11: 46185.733 | C11: FILT_G | D11: Follow Up | F11: Organic | G11: 1-100 | H11: =IF(OR(E11<>"",D11="Verified", D11="Service Done"),1,0) -> 0 | I11: =_xlfn.XLOOKUP(C11,Team_Legend!A:A,Team_Legend!B:B,"",0) -> Filteration | J11: =IF(H11=1,IF(I11="Sales","OK","Converted - Owner not Sales"),"")
A12: Lead_011 | B12: 46197.894 | C12: FILT_A | D12: Offer Pitched | F12: Google Paid | G12: 500+ | H12: =IF(OR(E12<>"",D12="Verified", D12="Service Done"),1,0) -> 0 | I12: =_xlfn.XLOOKUP(C12,Team_Legend!A:A,Team_Legend!B:B,"",0) -> Filteration | J12: =IF(H12=1,IF(I12="Sales","OK","Converted - Owner not Sales"),"")
A13: Lead_012 | B13: 46188.52 | C13: FILT_A | D13: Follow-up in Future | F13: Google Paid | G13: 1-100 | H13: =IF(OR(E13<>"",D13="Verified", D13="Service Done"),1,0) -> 0 | I13: =_xlfn.XLOOKUP(C13,Team_Legend!A:A,Team_Legend!B:B,"",0) -> Filteration | J13: =IF(H13=1,IF(I13="Sales","OK","Converted - Owner not Sales"),"")
A14: Lead_013 | B14: 46203.617 | C14: SALES_F | D14: Verified | E14: 46213.909 | F14: App | G14: 1-100 | H14: =IF(OR(E14<>"",D14="Verified", D14="Service Done"),1,0) -> 1 | I14: =_xlfn.XLOOKUP(C14,Team_Legend!A:A,Team_Legend!B:B,"",0) -> Sales | J14: =IF(H14=1,IF(I14="Sales","OK","Converted - Owner not Sales"),"") -> OK
A15: Lead_014 | B15: 46190.815 | C15: FILT_B | D15: Junk | F15: Meta | G15: 500+ | H15: =IF(OR(E15<>"",D15="Verified", D15="Service Done"),1,0) -> 0 | I15: =_xlfn.XLOOKUP(C15,Team_Legend!A:A,Team_Legend!B:B,"",0) -> Filteration | J15: =IF(H15=1,IF(I15="Sales","OK","Converted - Owner not Sales"),"")
A16: Lead_015 | B16: 46198.381 | C16: FILT_E | D16: Follow-up in Future | F16: Organic | G16: 1-100 | H16: =IF(OR(E16<>"",D16="Verified", D16="Service Done"),1,0) -> 0 | I16: =_xlfn.XLOOKUP(C16,Team_Legend!A:A,Team_Legend!B:B,"",0) -> Filteration | J16: =IF(H16=1,IF(I16="Sales","OK","Converted - Owner not Sales"),"")
A17: Lead_016 | B17: 46199.851 | C17: FILT_G | D17: Not Connected | F17: Organic | G17: 1-100 | H17: =IF(OR(E17<>"",D17="Verified", D17="Service Done"),1,0) -> 0 | I17: =_xlfn.XLOOKUP(C17,Team_Legend!A:A,Team_Legend!B:B,"",0) -> Filteration | J17: =IF(H17=1,IF(I17="Sales","OK","Converted - Owner not Sales"),"")
A18: Lead_017 | B18: 46196.645 | C18: FILT_D | F18: Meta | G18: 100-300 | H18: =IF(OR(E18<>"",D18="Verified", D18="Service Done"),1,0) -> 0 | I18: =_xlfn.XLOOKUP(C18,Team_Legend!A:A,Team_Legend!B:B,"",0) -> Filteration | J18: =IF(H18=1,IF(I18="Sales","OK","Converted - Owner not Sales"),"")
A19: Lead_018 | B19: 46204.604 | C19: FILT_F | D19: Verified | E19: 46205.937 | F19: Organic | G19: 1-100 | H19: =IF(OR(E19<>"",D19="Verified", D19="Service Done"),1,0) -> 1 | I19: =_xlfn.XLOOKUP(C19,Team_Legend!A:A,Team_Legend!B:B,"",0) -> Filteration | J19: =IF(H19=1,IF(I19="Sales","OK","Converted - Owner not Sales"),"") -> Converted - Owner not Sales
A20: Lead_019 | B20: 46182.205 | C20: FILT_D | D20: Verification Pending | F20: App | G20: 500+ | H20: =IF(OR(E20<>"",D20="Verified", D20="Service Done"),1,0) -> 0 | I20: =_xlfn.XLOOKUP(C20,Team_Legend!A:A,Team_Legend!B:B,"",0) -> Filteration | J20: =IF(H20=1,IF(I20="Sales","OK","Converted - Owner not Sales"),"")
A21: Lead_020 | B21: 46204.79 | C21: FILT_G | D21: Not Connected | F21: Organic | G21: Just starting out | H21: =IF(OR(E21<>"",D21="Verified", D21="Service Done"),1,0) -> 0 | I21: =_xlfn.XLOOKUP(C21,Team_Legend!A:A,Team_Legend!B:B,"",0) -> Filteration | J21: =IF(H21=1,IF(I21="Sales","OK","Converted - Owner not Sales"),"")
A22: Lead_021 | B22: 46205.396 | C22: OTHER_2 | D22: Not Connected | F22: Organic | G22: Just starting out | H22: =IF(OR(E22<>"",D22="Verified", D22="Service Done"),1,0) -> 0 | I22: =_xlfn.XLOOKUP(C22,Team_Legend!A:A,Team_Legend!B:B,"",0) -> Other / historical | J22: =IF(H22=1,IF(I22="Sales","OK","Converted - Owner not Sales"),"")
A23: Lead_022 | B23: 46186.746 | C23: FILT_A | D23: Not Interested | F23: Facebook | G23: 100-300 | H23: =IF(OR(E23<>"",D23="Verified", D23="Service Done"),1,0) -> 0 | I23: =_xlfn.XLOOKUP(C23,Team_Legend!A:A,Team_Legend!B:B,"",0) -> Filteration | J23: =IF(H23=1,IF(I23="Sales","OK","Converted - Owner not Sales"),"")
A24: Lead_023 | B24: 46181.466 | C24: FILT_E | D24: Call Back | F24: App | G24: Just starting out | H24: =IF(OR(E24<>"",D24="Verified", D24="Service Done"),1,0) -> 0 | I24: =_xlfn.XLOOKUP(C24,Team_Legend!A:A,Team_Legend!B:B,"",0) -> Filteration | J24: =IF(H24=1,IF(I24="Sales","OK","Converted - Owner not Sales"),"")
A25: Lead_024 | B25: 46202.84 | C25: FILT_G | D25: Junk | F25: Organic | G25: 300-500 | H25: =IF(OR(E25<>"",D25="Verified", D25="Service Done"),1,0) -> 0 | I25: =_xlfn.XLOOKUP(C25,Team_Legend!A:A,Team_Legend!B:B,"",0) -> Filteration | J25: =IF(H25=1,IF(I25="Sales","OK","Converted - Owner not Sales"),"")
A26: Lead_025 | B26: 46195.454 | C26: FILT_C | D26: Verified | E26: 46210.62 | F26: Organic | G26: Just starting out | H26: =IF(OR(E26<>"",D26="Verified", D26="Service Done"),1,0) -> 1 | I26: =_xlfn.XLOOKUP(C26,Team_Legend!A:A,Team_Legend!B:B,"",0) -> Filteration | J26: =IF(H26=1,IF(I26="Sales","OK","Converted - Owner not Sales"),"") -> Converted - Owner not Sales
A27: Lead_026 | B27: 46198.046 | C27: FILT_A | D27: Not Connected | F27: Organic | G27: 100-300 | H27: =IF(OR(E27<>"",D27="Verified", D27="Service Done"),1,0) -> 0 | I27: =_xlfn.XLOOKUP(C27,Team_Legend!A:A,Team_Legend!B:B,"",0) -> Filteration | J27: =IF(H27=1,IF(I27="Sales","OK","Converted - Owner not Sales"),"")
A28: Lead_027 | B28: 46197.615 | C28: FILT_D | D28: Junk | F28: Organic | G28: Just starting out | H28: =IF(OR(E28<>"",D28="Verified", D28="Service Done"),1,0) -> 0 | I28: =_xlfn.XLOOKUP(C28,Team_Legend!A:A,Team_Legend!B:B,"",0) -> Filteration | J28: =IF(H28=1,IF(I28="Sales","OK","Converted - Owner not Sales"),"")
A29: Lead_028 | B29: 46190.781 | C29: FILT_C | D29: Follow Up | F29: Meta | G29: 1-100 | H29: =IF(OR(E29<>"",D29="Verified", D29="Service Done"),1,0) -> 0 | I29: =_xlfn.XLOOKUP(C29,Team_Legend!A:A,Team_Legend!B:B,"",0) -> Filteration | J29: =IF(H29=1,IF(I29="Sales","OK","Converted - Owner not Sales"),"")
A30: Lead_029 | B30: 46202.491 | C30: FILT_A | D30: Junk | F30: Organic | G30: 1-100 | H30: =IF(OR(E30<>"",D30="Verified", D30="Service Done"),1,0) -> 0 | I30: =_xlfn.XLOOKUP(C30,Team_Legend!A:A,Team_Legend!B:B,"",0) -> Filteration | J30: =IF(H30=1,IF(I30="Sales","OK","Converted - Owner not Sales"),"")
A31: Lead_030 | B31: 46193.361 | C31: FILT_B | D31: Not Connected | F31: Google Paid | G31: 100-300 | H31: =IF(OR(E31<>"",D31="Verified", D31="Service Done"),1,0) -> 0 | I31: =_xlfn.XLOOKUP(C31,Team_Legend!A:A,Team_Legend!B:B,"",0) -> Filteration | J31: =IF(H31=1,IF(I31="Sales","OK","Converted - Owner not Sales"),"")
A32: Lead_031 | B32: 46193.469 | C32: FILT_B | D32: Verification Pending | F32: App | G32: Just starting out | H32: =IF(OR(E32<>"",D32="Verified", D32="Service Done"),1,0) -> 0 | I32: =_xlfn.XLOOKUP(C32,Team_Legend!A:A,Team_Legend!B:B,"",0) -> Filteration | J32: =IF(H32=1,IF(I32="Sales","OK","Converted - Owner not Sales"),"")
A33: Lead_032 | B33: 46190.512 | C33: FILT_A | D33: Offer Negotiation | F33: Organic | G33: 1-100 | H33: =IF(OR(E33<>"",D33="Verified", D33="Service Done"),1,0) -> 0 | I33: =_xlfn.XLOOKUP(C33,Team_Legend!A:A,Team_Legend!B:B,"",0) -> Filteration | J33: =IF(H33=1,IF(I33="Sales","OK","Converted - Owner not Sales"),"")
A34: Lead_033 | B34: 46206.587 | C34: FILT_A | D34: Uncontactable | F34: Google Paid | G34: 500+ | H34: =IF(OR(E34<>"",D34="Verified", D34="Service Done"),1,0) -> 0 | I34: =_xlfn.XLOOKUP(C34,Team_Legend!A:A,Team_Legend!B:B,"",0) -> Filteration | J34: =IF(H34=1,IF(I34="Sales","OK","Converted - Owner not Sales"),"")
A35: Lead_034 | B35: 46200.669 | C35: FILT_F | D35: Follow-up in Future | F35: Meta | G35: 1-100 | H35: =IF(OR(E35<>"",D35="Verified", D35="Service Done"),1,0) -> 0 | I35: =_xlfn.XLOOKUP(C35,Team_Legend!A:A,Team_Legend!B:B,"",0) -> Filteration | J35: =IF(H35=1,IF(I35="Sales","OK","Converted - Owner not Sales"),"")
A36: Lead_035 | B36: 46182.768 | C36: SALES_B | D36: Document & Details Pending | F36: Google Paid | G36: Just starting out | H36: =IF(OR(E36<>"",D36="Verified", D36="Service Done"),1,0) -> 0 | I36: =_xlfn.XLOOKUP(C36,Team_Legend!A:A,Team_Legend!B:B,"",0) -> Sales | J36: =IF(H36=1,IF(I36="Sales","OK","Converted - Owner not Sales"),"")
A37: Lead_036 | B37: 46205.59 | C37: FILT_C | D37: New Lead | F37: App | G37: 300-500 | H37: =IF(OR(E37<>"",D37="Verified", D37="Service Done"),1,0) -> 0 | I37: =_xlfn.XLOOKUP(C37,Team_Legend!A:A,Team_Legend!B:B,"",0) -> Filteration | J37: =IF(H37=1,IF(I37="Sales","OK","Converted - Owner not Sales"),"")
A38: Lead_037 | B38: 46188.366 | C38: OTHER_1 | D38: Call Back | F38: Google Paid | G38: 300-500 | H38: =IF(OR(E38<>"",D38="Verified", D38="Service Done"),1,0) -> 0 | I38: =_xlfn.XLOOKUP(C38,Team_Legend!A:A,Team_Legend!B:B,"",0) -> Other / historical | J38: =IF(H38=1,IF(I38="Sales","OK","Converted - Owner not Sales"),"")
... A43: Lead_042 | B43: 46185.222 | C43: FILT_E | D43: Not Connected | F43: Google Paid | G43: Just starting out | H43: =IF(OR(E43<>"",D43="Verified", D43="Service Done"),1,0) -> 0 | I43: =_xlfn.XLOOKUP(C43,Team_Legend!A:A,Team_Legend!B:B,"",0) -> Filteration | J43: =IF(H43=1,IF(I43="Sales","OK","Converted - Owner not Sales"),"")
A44: Lead_043 | B44: 46185.262 | C44: FILT_A | D44: Verified | E44: 46199.47 | F44: Organic | G44: 500+ | H44: =IF(OR(E44<>"",D44="Verified", D44="Service Done"),1,0) -> 1 | I44: =_xlfn.XLOOKUP(C44,Team_Legend!A:A,Team_Legend!B:B,"",0) -> Filteration | J44: =IF(H44=1,IF(I44="Sales","OK","Converted - Owner not Sales"),"") -> Converted - Owner not Sales
...

Sheet Team_Legend
A1: Agent Code | B1: Team | C1: Sales Buddy (for Filteration only)
A2: FILT_A | B2: Filteration | C2: SALES_A
A3: FILT_B | B3: Filteration | C3: SALES_B
A4: FILT_C | B4: Filteration | C4: SALES_C
A5: FILT_D | B5: Filteration | C5: SALES_D
A6: FILT_E | B6: Filteration | C6: SALES_E
A7: FILT_F | B7: Filteration | C7: SALES_F
A8: FILT_G | B8: Filteration | C8: SALES_F
A9: SALES_A | B9: Sales
A10: SALES_B | B10: Sales
A11: SALES_C | B11: Sales
A12: SALES_D | B12: Sales
A13: SALES_E | B13: Sales
A14: SALES_F | B14: Sales
A15: OTHER_1 | B15: Other / historical
A16: OTHER_2 | B16: Other / historical

Sheet Lead_Timestamps
A1: Lead ID | B1: Owner | C1: Created On | D1: First Phone Call | E1: Latest Follow Up | F1: Interested | G1: Offer Pitched | H1: Verified | I1: Service Done | J1: First Response Working Hours | K1: Response bucket | L1: Conversion Falg
A2: Lead_001 | B2: FILT_E | C2: 46207.58 | D2: 46207.594 | E2: 46208.969 | J2: =IF(D2="","",ROUND(24*MAX(0,(NETWORKDAYS.INTL(INT(C2),INT(D2),11)-1)*(TIME(18,30,0)-TIME(10,0,0))+IF(NETWORKDAYS.INTL(INT(D2),INT(D2),11),MEDIAN(MOD(D2,1),TIME(18,30,0),TIME(10,0,0)),TIME(18,30,0))-IF(NETWORKDAYS.INTL(INT(C2),INT(C2),11),MEDIAN(MOD(C2,1),TIME(18,30,0),TIME(10,0,0)),TIME(10,0,0))),4)) -> 0.3333 | K2: {=IF(D2="","No Call",_xlfn.IFS(J2<=0.25,"<=15 min",J2<=0.5,"16-30 min",J2<=1,"31-60 min",TRUE,">60 min"))} -> 16-30 min | L2: =_xlfn.XLOOKUP(A2,Lead_Data!A:A,Lead_Data!H:H,0) -> 0
A3: Lead_002 | B3: FILT_G | C3: 46192.37 | D3: 46192.447 | J3: =IF(D3="","",ROUND(24*MAX(0,(NETWORKDAYS.INTL(INT(C3),INT(D3),11)-1)*(TIME(18,30,0)-TIME(10,0,0))+IF(NETWORKDAYS.INTL(INT(D3),INT(D3),11),MEDIAN(MOD(D3,1),TIME(18,30,0),TIME(10,0,0)),TIME(18,30,0))-IF(NETWORKDAYS.INTL(INT(C3),INT(C3),11),MEDIAN(MOD(C3,1),TIME(18,30,0),TIME(10,0,0)),TIME(10,0,0))),4)) -> 0.7168 | K3: {=IF(D3="","No Call",_xlfn.IFS(J3<=0.25,"<=15 min",J3<=0.5,"16-30 min",J3<=1,"31-60 min",TRUE,">60 min"))} -> 31-60 min | L3: =_xlfn.XLOOKUP(A3,Lead_Data!A:A,Lead_Data!H:H,0) -> 0
A4: Lead_003 | B4: FILT_F | C4: 46203.958 | D4: 46204.435 | J4: =IF(D4="","",ROUND(24*MAX(0,(NETWORKDAYS.INTL(INT(C4),INT(D4),11)-1)*(TIME(18,30,0)-TIME(10,0,0))+IF(NETWORKDAYS.INTL(INT(D4),INT(D4),11),MEDIAN(MOD(D4,1),TIME(18,30,0),TIME(10,0,0)),TIME(18,30,0))-IF(NETWORKDAYS.INTL(INT(C4),INT(C4),11),MEDIAN(MOD(C4,1),TIME(18,30,0),TIME(10,0,0)),TIME(10,0,0))),4)) -> 0.45 | K4: {=IF(D4="","No Call",_xlfn.IFS(J4<=0.25,"<=15 min",J4<=0.5,"16-30 min",J4<=1,"31-60 min",TRUE,">60 min"))} -> 16-30 min | L4: =_xlfn.XLOOKUP(A4,Lead_Data!A:A,Lead_Data!H:H,0) -> 0
A5: Lead_004 | B5: FILT_C | C5: 46202.404 | D5: 46202.422 | E5: 46202.672 | F5: 46202.547 | G5: 46202.631 | J5: =IF(D5="","",ROUND(24*MAX(0,(NETWORKDAYS.INTL(INT(C5),INT(D5),11)-1)*(TIME(18,30,0)-TIME(10,0,0))+IF(NETWORKDAYS.INTL(INT(D5),INT(D5),11),MEDIAN(MOD(D5,1),TIME(18,30,0),TIME(10,0,0)),TIME(18,30,0))-IF(NETWORKDAYS.INTL(INT(C5),INT(C5),11),MEDIAN(MOD(C5,1),TIME(18,30,0),TIME(10,0,0)),TIME(10,0,0))),4)) -> 0.1336 | K5: {=IF(D5="","No Call",_xlfn.IFS(J5<=0.25,"<=15 min",J5<=0.5,"16-30 min",J5<=1,"31-60 min",TRUE,">60 min"))} -> <=15 min | L5: =_xlfn.XLOOKUP(A5,Lead_Data!A:A,Lead_Data!H:H,0) -> 0
A6: Lead_005 | B6: FILT_G | C6: 46208.58 | D6: 46209.417 | E6: 46210.751 | J6: =IF(D6="","",ROUND(24*MAX(0,(NETWORKDAYS.INTL(INT(C6),INT(D6),11)-1)*(TIME(18,30,0)-TIME(10,0,0))+IF(NETWORKDAYS.INTL(INT(D6),INT(D6),11),MEDIAN(MOD(D6,1),TIME(18,30,0),TIME(10,0,0)),TIME(18,30,0))-IF(NETWORKDAYS.INTL(INT(C6),INT(C6),11),MEDIAN(MOD(C6,1),TIME(18,30,0),TIME(10,0,0)),TIME(10,0,0))),4)) -> 0.0168 | K6: {=IF(D6="","No Call",_xlfn.IFS(J6<=0.25,"<=15 min",J6<=0.5,"16-30 min",J6<=1,"31-60 min",TRUE,">60 min"))} -> <=15 min | L6: =_xlfn.XLOOKUP(A6,Lead_Data!A:A,Lead_Data!H:H,0) -> 0
A7: Lead_006 | B7: FILT_A | C7: 46198.813 | D7: 46199.426 | E7: 46200.759 | J7: =IF(D7="","",ROUND(24*MAX(0,(NETWORKDAYS.INTL(INT(C7),INT(D7),11)-1)*(TIME(18,30,0)-TIME(10,0,0))+IF(NETWORKDAYS.INTL(INT(D7),INT(D7),11),MEDIAN(MOD(D7,1),TIME(18,30,0),TIME(10,0,0)),TIME(18,30,0))-IF(NETWORKDAYS.INTL(INT(C7),INT(C7),11),MEDIAN(MOD(C7,1),TIME(18,30,0),TIME(10,0,0)),TIME(10,0,0))),4)) -> 0.2169 | K7: {=IF(D7="","No Call",_xlfn.IFS(J7<=0.25,"<=15 min",J7<=0.5,"16-30 min",J7<=1,"31-60 min",TRUE,">60 min"))} -> <=15 min | L7: =_xlfn.XLOOKUP(A7,Lead_Data!A:A,Lead_Data!H:H,0) -> 0
A8: Lead_007 | B8: FILT_A | C8: 46207.521 | D8: 46207.526 | J8: =IF(D8="","",ROUND(24*MAX(0,(NETWORKDAYS.INTL(INT(C8),INT(D8),11)-1)*(TIME(18,30,0)-TIME(10,0,0))+IF(NETWORKDAYS.INTL(INT(D8),INT(D8),11),MEDIAN(MOD(D8,1),TIME(18,30,0),TIME(10,0,0)),TIME(18,30,0))-IF(NETWORKDAYS.INTL(INT(C8),INT(C8),11),MEDIAN(MOD(C8,1),TIME(18,30,0),TIME(10,0,0)),TIME(10,0,0))),4)) -> 0.1167 | K8: {=IF(D8="","No Call",_xlfn.IFS(J8<=0.25,"<=15 min",J8<=0.5,"16-30 min",J8<=1,"31-60 min",TRUE,">60 min"))} -> <=15 min | L8: =_xlfn.XLOOKUP(A8,Lead_Data!A:A,Lead_Data!H:H,0) -> 0
A9: Lead_008 | B9: FILT_D | C9: 46193.494 | D9: 46193.495 | J9: =IF(D9="","",ROUND(24*MAX(0,(NETWORKDAYS.INTL(INT(C9),INT(D9),11)-1)*(TIME(18,30,0)-TIME(10,0,0))+IF(NETWORKDAYS.INTL(INT(D9),INT(D9),11),MEDIAN(MOD(D9,1),TIME(18,30,0),TIME(10,0,0)),TIME(18,30,0))-IF(NETWORKDAYS.INTL(INT(C9),INT(C9),11),MEDIAN(MOD(C9,1),TIME(18,30,0),TIME(10,0,0)),TIME(10,0,0))),4)) -> 0.0167 | K9: {=IF(D9="","No Call",_xlfn.IFS(J9<=0.25,"<=15 min",J9<=0.5,"16-30 min",J9<=1,"31-60 min",TRUE,">60 min"))} -> <=15 min | L9: =_xlfn.XLOOKUP(A9,Lead_Data!A:A,Lead_Data!H:H,0) -> 0
A10: Lead_009 | B10: FILT_D | C10: 46206.771 | D10: 46207.44 | E10: 46208.982 | J10: =IF(D10="","",ROUND(24*MAX(0,(NETWORKDAYS.INTL(INT(C10),INT(D10),11)-1)*(TIME(18,30,0)-TIME(10,0,0))+IF(NETWORKDAYS.INTL(INT(D10),INT(D10),11),MEDIAN(MOD(D10,1),TIME(18,30,0),TIME(10,0,0)),TIME(18,30,0))-IF(NETWORKDAYS.INTL(INT(C10),INT(C10),11),MEDIAN(MOD(C10,1),TIME(18,30,0),TIME(10,0,0)),TIME(10,0,0))),4)) -> 0.5667 | K10: {=IF(D10="","No Call",_xlfn.IFS(J10<=0.25,"<=15 min",J10<=0.5,"16-30 min",J10<=1,"31-60 min",TRUE,">60 min"))} -> 31-60 min | L10: =_xlfn.XLOOKUP(A10,Lead_Data!A:A,Lead_Data!H:H,0) -> 0
A11: Lead_010 | B11: FILT_G | C11: 46185.733 | D11: 46185.765 | E11: 46186.182 | J11: =IF(D11="","",ROUND(24*MAX(0,(NETWORKDAYS.INTL(INT(C11),INT(D11),11)-1)*(TIME(18,30,0)-TIME(10,0,0))+IF(NETWORKDAYS.INTL(INT(D11),INT(D11),11),MEDIAN(MOD(D11,1),TIME(18,30,0),TIME(10,0,0)),TIME(18,30,0))-IF(NETWORKDAYS.INTL(INT(C11),INT(C11),11),MEDIAN(MOD(C11,1),TIME(18,30,0),TIME(10,0,0)),TIME(10,0,0))),4)) -> 0.7667 | K11: {=IF(D11="","No Call",_xlfn.IFS(J11<=0.25,"<=15 min",J11<=0.5,"16-30 min",J11<=1,"31-60 min",TRUE,">60 min"))} -> 31-60 min | L11: =_xlfn.XLOOKUP(A11,Lead_Data!A:A,Lead_Data!H:H,0) -> 0
A12: Lead_011 | B12: FILT_A | C12: 46197.894 | D12: 46198.424 | E12: 46199.299 | F12: 46199.258 | G12: 46200.383 | J12: =IF(D12="","",ROUND(24*MAX(0,(NETWORKDAYS.INTL(INT(C12),INT(D12),11)-1)*(TIME(18,30,0)-TIME(10,0,0))+IF(NETWORKDAYS.INTL(INT(D12),INT(D12),11),MEDIAN(MOD(D12,1),TIME(18,30,0),TIME(10,0,0)),TIME(18,30,0))-IF(NETWORKDAYS.INTL(INT(C12),INT(C12),11),MEDIAN(MOD(C12,1),TIME(18,30,0),TIME(10,0,0)),TIME(10,0,0))),4)) -> 0.1835 | K12: {=IF(D12="","No Call",_xlfn.IFS(J12<=0.25,"<=15 min",J12<=0.5,"16-30 min",J12<=1,"31-60 min",TRUE,">60 min"))} -> <=15 min | L12: =_xlfn.XLOOKUP(A12,Lead_Data!A:A,Lead_Data!H:H,0) -> 0
A13: Lead_012 | B13: FILT_A | C13: 46188.52 | D13: 46188.53 | E13: 46189.822 | J13: =IF(D13="","",ROUND(24*MAX(0,(NETWORKDAYS.INTL(INT(C13),INT(D13),11)-1)*(TIME(18,30,0)-TIME(10,0,0))+IF(NETWORKDAYS.INTL(INT(D13),INT(D13),11),MEDIAN(MOD(D13,1),TIME(18,30,0),TIME(10,0,0)),TIME(18,30,0))-IF(NETWORKDAYS.INTL(INT(C13),INT(C13),11),MEDIAN(MOD(C13,1),TIME(18,30,0),TIME(10,0,0)),TIME(10,0,0))),4)) -> 0.2333 | K13: {=IF(D13="","No Call",_xlfn.IFS(J13<=0.25,"<=15 min",J13<=0.5,"16-30 min",J13<=1,"31-60 min",TRUE,">60 min"))} -> <=15 min | L13: =_xlfn.XLOOKUP(A13,Lead_Data!A:A,Lead_Data!H:H,0) -> 0
A14: Lead_013 | B14: SALES_F | C14: 46203.617 | D14: 46203.64 | E14: 46203.807 | F14: 46204.223 | G14: 46205.473 | H14: 46205.932 | J14: =IF(D14="","",ROUND(24*MAX(0,(NETWORKDAYS.INTL(INT(C14),INT(D14),11)-1)*(TIME(18,30,0)-TIME(10,0,0))+IF(NETWORKDAYS.INTL(INT(D14),INT(D14),11),MEDIAN(MOD(D14,1),TIME(18,30,0),TIME(10,0,0)),TIME(18,30,0))-IF(NETWORKDAYS.INTL(INT(C14),INT(C14),11),MEDIAN(MOD(C14,1),TIME(18,30,0),TIME(10,0,0)),TIME(10,0,0))),4)) -> 0.55 | K14: {=IF(D14="","No Call",_xlfn.IFS(J14<=0.25,"<=15 min",J14<=0.5,"16-30 min",J14<=1,"31-60 min",TRUE,">60 min"))} -> 31-60 min | L14: =_xlfn.XLOOKUP(A14,Lead_Data!A:A,Lead_Data!H:H,0) -> 1
A15: Lead_014 | B15: FILT_B | C15: 46190.815 | D15: 46191.433 | J15: =IF(D15="","",ROUND(24*MAX(0,(NETWORKDAYS.INTL(INT(C15),INT(D15),11)-1)*(TIME(18,30,0)-TIME(10,0,0))+IF(NETWORKDAYS.INTL(INT(D15),INT(D15),11),MEDIAN(MOD(D15,1),TIME(18,30,0),TIME(10,0,0)),TIME(18,30,0))-IF(NETWORKDAYS.INTL(INT(C15),INT(C15),11),MEDIAN(MOD(C15,1),TIME(18,30,0),TIME(10,0,0)),TIME(10,0,0))),4)) -> 0.4002 | K15: {=IF(D15="","No Call",_xlfn.IFS(J15<=0.25,"<=15 min",J15<=0.5,"16-30 min",J15<=1,"31-60 min",TRUE,">60 min"))} -> 16-30 min | L15: =_xlfn.XLOOKUP(A15,Lead_Data!A:A,Lead_Data!H:H,0) -> 0
A16: Lead_015 | B16: FILT_E | C16: 46198.381 | D16: 46198.426 | E16: 46200.135 | J16: =IF(D16="","",ROUND(24*MAX(0,(NETWORKDAYS.INTL(INT(C16),INT(D16),11)-1)*(TIME(18,30,0)-TIME(10,0,0))+IF(NETWORKDAYS.INTL(INT(D16),INT(D16),11),MEDIAN(MOD(D16,1),TIME(18,30,0),TIME(10,0,0)),TIME(18,30,0))-IF(NETWORKDAYS.INTL(INT(C16),INT(C16),11),MEDIAN(MOD(C16,1),TIME(18,30,0),TIME(10,0,0)),TIME(10,0,0))),4)) -> 0.2336 | K16: {=IF(D16="","No Call",_xlfn.IFS(J16<=0.25,"<=15 min",J16<=0.5,"16-30 min",J16<=1,"31-60 min",TRUE,">60 min"))} -> <=15 min | L16: =_xlfn.XLOOKUP(A16,Lead_Data!A:A,Lead_Data!H:H,0) -> 0
A17: Lead_016 | B17: FILT_G | C17: 46199.851 | D17: 46200.463 | E17: 46202.213 | J17: =IF(D17="","",ROUND(24*MAX(0,(NETWORKDAYS.INTL(INT(C17),INT(D17),11)-1)*(TIME(18,30,0)-TIME(10,0,0))+IF(NETWORKDAYS.INTL(INT(D17),INT(D17),11),MEDIAN(MOD(D17,1),TIME(18,30,0),TIME(10,0,0)),TIME(18,30,0))-IF(NETWORKDAYS.INTL(INT(C17),INT(C17),11),MEDIAN(MOD(C17,1),TIME(18,30,0),TIME(10,0,0)),TIME(10,0,0))),4)) -> 1.1003 | K17: {=IF(D17="","No Call",_xlfn.IFS(J17<=0.25,"<=15 min",J17<=0.5,"16-30 min",J17<=1,"31-60 min",TRUE,">60 min"))} -> >60 min | L17: =_xlfn.XLOOKUP(A17,Lead_Data!A:A,Lead_Data!H:H,0) -> 0
A18: Lead_017 | B18: FILT_D | C18: 46196.645 | D18: 46196.653 | J18: =IF(D18="","",ROUND(24*MAX(0,(NETWORKDAYS.INTL(INT(C18),INT(D18),11)-1)*(TIME(18,30,0)-TIME(10,0,0))+IF(NETWORKDAYS.INTL(INT(D18),INT(D18),11),MEDIAN(MOD(D18,1),TIME(18,30,0),TIME(10,0,0)),TIME(18,30,0))-IF(NETWORKDAYS.INTL(INT(C18),INT(C18),11),MEDIAN(MOD(C18,1),TIME(18,30,0),TIME(10,0,0)),TIME(10,0,0))),4)) -> 0.2 | K18: {=IF(D18="","No Call",_xlfn.IFS(J18<=0.25,"<=15 min",J18<=0.5,"16-30 min",J18<=1,"31-60 min",TRUE,">60 min"))} -> <=15 min | L18: =_xlfn.XLOOKUP(A18,Lead_Data!A:A,Lead_Data!H:H,0) -> 0
A19: Lead_018 | B19: FILT_F | C19: 46204.604 | D19: 46204.615 | E19: 46205.032 | F19: 46205.323 | G19: 46205.99 | H19: 46206.99 | J19: =IF(D19="","",ROUND(24*MAX(0,(NETWORKDAYS.INTL(INT(C19),INT(D19),11)-1)*(TIME(18,30,0)-TIME(10,0,0))+IF(NETWORKDAYS.INTL(INT(D19),INT(D19),11),MEDIAN(MOD(D19,1),TIME(18,30,0),TIME(10,0,0)),TIME(18,30,0))-IF(NETWORKDAYS.INTL(INT(C19),INT(C19),11),MEDIAN(MOD(C19,1),TIME(18,30,0),TIME(10,0,0)),TIME(10,0,0))),4)) -> 0.2667 | K19: {=IF(D19="","No Call",_xlfn.IFS(J19<=0.25,"<=15 min",J19<=0.5,"16-30 min",J19<=1,"31-60 min",TRUE,">60 min"))} -> 16-30 min | L19: =_xlfn.XLOOKUP(A19,Lead_Data!A:A,Lead_Data!H:H,0) -> 1
A20: Lead_019 | B20: FILT_D | C20: 46182.205 | D20: 46182.433 | E20: 46183.433 | F20: 46183.225 | G20: 46183.892 | J20: =IF(D20="","",ROUND(24*MAX(0,(NETWORKDAYS.INTL(INT(C20),INT(D20),11)-1)*(TIME(18,30,0)-TIME(10,0,0))+IF(NETWORKDAYS.INTL(INT(D20),INT(D20),11),MEDIAN(MOD(D20,1),TIME(18,30,0),TIME(10,0,0)),TIME(18,30,0))-IF(NETWORKDAYS.INTL(INT(C20),INT(C20),11),MEDIAN(MOD(C20,1),TIME(18,30,0),TIME(10,0,0)),TIME(10,0,0))),4)) -> 0.4 | K20: {=IF(D20="","No Call",_xlfn.IFS(J20<=0.25,"<=15 min",J20<=0.5,"16-30 min",J20<=1,"31-60 min",TRUE,">60 min"))} -> 16-30 min | L20: =_xlfn.XLOOKUP(A20,Lead_Data!A:A,Lead_Data!H:H,0) -> 0
A21: Lead_020 | B21: FILT_G | C21: 46204.79 | D21: 46205.433 | E21: 46206.975 | J21: =IF(D21="","",ROUND(24*MAX(0,(NETWORKDAYS.INTL(INT(C21),INT(D21),11)-1)*(TIME(18,30,0)-TIME(10,0,0))+IF(NETWORKDAYS.INTL(INT(D21),INT(D21),11),MEDIAN(MOD(D21,1),TIME(18,30,0),TIME(10,0,0)),TIME(18,30,0))-IF(NETWORKDAYS.INTL(INT(C21),INT(C21),11),MEDIAN(MOD(C21,1),TIME(18,30,0),TIME(10,0,0)),TIME(10,0,0))),4)) -> 0.4002 | K21: {=IF(D21="","No Call",_xlfn.IFS(J21<=0.25,"<=15 min",J21<=0.5,"16-30 min",J21<=1,"31-60 min",TRUE,">60 min"))} -> 16-30 min | L21: =_xlfn.XLOOKUP(A21,Lead_Data!A:A,Lead_Data!H:H,0) -> 0
A22: Lead_021 | B22: OTHER_2 | C22: 46205.396 | D22: 46205.444 | E22: 46207.194 | J22: =IF(D22="","",ROUND(24*MAX(0,(NETWORKDAYS.INTL(INT(C22),INT(D22),11)-1)*(TIME(18,30,0)-TIME(10,0,0))+IF(NETWORKDAYS.INTL(INT(D22),INT(D22),11),MEDIAN(MOD(D22,1),TIME(18,30,0),TIME(10,0,0)),TIME(18,30,0))-IF(NETWORKDAYS.INTL(INT(C22),INT(C22),11),MEDIAN(MOD(C22,1),TIME(18,30,0),TIME(10,0,0)),TIME(10,0,0))),4)) -> 0.6502 | K22: {=IF(D22="","No Call",_xlfn.IFS(J22<=0.25,"<=15 min",J22<=0.5,"16-30 min",J22<=1,"31-60 min",TRUE,">60 min"))} -> 31-60 min | L22: =_xlfn.XLOOKUP(A22,Lead_Data!A:A,Lead_Data!H:H,0) -> 0
A23: Lead_022 | B23: FILT_A | C23: 46186.746 | D23: 46186.752 | J23: =IF(D23="","",ROUND(24*MAX(0,(NETWORKDAYS.INTL(INT(C23),INT(D23),11)-1)*(TIME(18,30,0)-TIME(10,0,0))+IF(NETWORKDAYS.INTL(INT(D23),INT(D23),11),MEDIAN(MOD(D23,1),TIME(18,30,0),TIME(10,0,0)),TIME(18,30,0))-IF(NETWORKDAYS.INTL(INT(C23),INT(C23),11),MEDIAN(MOD(C23,1),TIME(18,30,0),TIME(10,0,0)),TIME(10,0,0))),4)) -> 0.15 | K23: {=IF(D23="","No Call",_xlfn.IFS(J23<=0.25,"<=15 min",J23<=0.5,"16-30 min",J23<=1,"31-60 min",TRUE,">60 min"))} -> <=15 min | L23: =_xlfn.XLOOKUP(A23,Lead_Data!A:A,Lead_Data!H:H,0) -> 0
A24: Lead_023 | B24: FILT_E | C24: 46181.466 | D24: 46181.476 | E24: 46182.476 | J24: =IF(D24="","",ROUND(24*MAX(0,(NETWORKDAYS.INTL(INT(C24),INT(D24),11)-1)*(TIME(18,30,0)-TIME(10,0,0))+IF(NETWORKDAYS.INTL(INT(D24),INT(D24),11),MEDIAN(MOD(D24,1),TIME(18,30,0),TIME(10,0,0)),TIME(18,30,0))-IF(NETWORKDAYS.INTL(INT(C24),INT(C24),11),MEDIAN(MOD(C24,1),TIME(18,30,0),TIME(10,0,0)),TIME(10,0,0))),4)) -> 0.25 | K24: {=IF(D24="","No Call",_xlfn.IFS(J24<=0.25,"<=15 min",J24<=0.5,"16-30 min",J24<=1,"31-60 min",TRUE,">60 min"))} -> <=15 min | L24: =_xlfn.XLOOKUP(A24,Lead_Data!A:A,Lead_Data!H:H,0) -> 0
A25: Lead_024 | B25: FILT_G | C25: 46202.84 | D25: 46203.434 | J25: =IF(D25="","",ROUND(24*MAX(0,(NETWORKDAYS.INTL(INT(C25),INT(D25),11)-1)*(TIME(18,30,0)-TIME(10,0,0))+IF(NETWORKDAYS.INTL(INT(D25),INT(D25),11),MEDIAN(MOD(D25,1),TIME(18,30,0),TIME(10,0,0)),TIME(18,30,0))-IF(NETWORKDAYS.INTL(INT(C25),INT(C25),11),MEDIAN(MOD(C25,1),TIME(18,30,0),TIME(10,0,0)),TIME(10,0,0))),4)) -> 0.4168 | K25: {=IF(D25="","No Call",_xlfn.IFS(J25<=0.25,"<=15 min",J25<=0.5,"16-30 min",J25<=1,"31-60 min",TRUE,">60 min"))} -> 16-30 min | L25: =_xlfn.XLOOKUP(A25,Lead_Data!A:A,Lead_Data!H:H,0) -> 0
A26: Lead_025 | B26: FILT_C | C26: 46195.454 | D26: 46195.464 | E26: 46196.381 | F26: 46196.047 | G26: 46196.922 | H26: 46198.381 | J26: =IF(D26="","",ROUND(24*MAX(0,(NETWORKDAYS.INTL(INT(C26),INT(D26),11)-1)*(TIME(18,30,0)-TIME(10,0,0))+IF(NETWORKDAYS.INTL(INT(D26),INT(D26),11),MEDIAN(MOD(D26,1),TIME(18,30,0),TIME(10,0,0)),TIME(18,30,0))-IF(NETWORKDAYS.INTL(INT(C26),INT(C26),11),MEDIAN(MOD(C26,1),TIME(18,30,0),TIME(10,0,0)),TIME(10,0,0))),4)) -> 0.25 | K26: {=IF(D26="","No Call",_xlfn.IFS(J26<=0.25,"<=15 min",J26<=0.5,"16-30 min",J26<=1,"31-60 min",TRUE,">60 min"))} -> <=15 min | L26: =_xlfn.XLOOKUP(A26,Lead_Data!A:A,Lead_Data!H:H,0) -> 1
A27: Lead_026 | B27: FILT_A | C27: 46198.046 | D27: 46198.424 | E27: 46200.382 | J27: =IF(D27="","",ROUND(24*MAX(0,(NETWORKDAYS.INTL(INT(C27),INT(D27),11)-1)*(TIME(18,30,0)-TIME(10,0,0))+IF(NETWORKDAYS.INTL(INT(D27),INT(D27),11),MEDIAN(MOD(D27,1),TIME(18,30,0),TIME(10,0,0)),TIME(18,30,0))-IF(NETWORKDAYS.INTL(INT(C27),INT(C27),11),MEDIAN(MOD(C27,1),TIME(18,30,0),TIME(10,0,0)),TIME(10,0,0))),4)) -> 0.1669 | K27: {=IF(D27="","No Call",_xlfn.IFS(J27<=0.25,"<=15 min",J27<=0.5,"16-30 min",J27<=1,"31-60 min",TRUE,">60 min"))} -> <=15 min | L27: =_xlfn.XLOOKUP(A27,Lead_Data!A:A,Lead_Data!H:H,0) -> 0
A28: Lead_027 | B28: FILT_D | C28: 46197.615 | D28: 46197.62 | J28: =IF(D28="","",ROUND(24*MAX(0,(NETWORKDAYS.INTL(INT(C28),INT(D28),11)-1)*(TIME(18,30,0)-TIME(10,0,0))+IF(NETWORKDAYS.INTL(INT(D28),INT(D28),11),MEDIAN(MOD(D28,1),TIME(18,30,0),TIME(10,0,0)),TIME(18,30,0))-IF(NETWORKDAYS.INTL(INT(C28),INT(C28),11),MEDIAN(MOD(C28,1),TIME(18,30,0),TIME(10,0,0)),TIME(10,0,0))),4)) -> 0.1167 | K28: {=IF(D28="","No Call",_xlfn.IFS(J28<=0.25,"<=15 min",J28<=0.5,"16-30 min",J28<=1,"31-60 min",TRUE,">60 min"))} -> <=15 min | L28: =_xlfn.XLOOKUP(A28,Lead_Data!A:A,Lead_Data!H:H,0) -> 0
A29: Lead_028 | B29: FILT_C | C29: 46190.781 | D29: 46191.431 | E29: 46193.389 | J29: =IF(D29="","",ROUND(24*MAX(0,(NETWORKDAYS.INTL(INT(C29),INT(D29),11)-1)*(TIME(18,30,0)-TIME(10,0,0))+IF(NETWORKDAYS.INTL(INT(D29),INT(D29),11),MEDIAN(MOD(D29,1),TIME(18,30,0),TIME(10,0,0)),TIME(18,30,0))-IF(NETWORKDAYS.INTL(INT(C29),INT(C29),11),MEDIAN(MOD(C29,1),TIME(18,30,0),TIME(10,0,0)),TIME(10,0,0))),4)) -> 0.3335 | K29: {=IF(D29="","No Call",_xlfn.IFS(J29<=0.25,"<=15 min",J29<=0.5,"16-30 min",J29<=1,"31-60 min",TRUE,">60 min"))} -> 16-30 min | L29: =_xlfn.XLOOKUP(A29,Lead_Data!A:A,Lead_Data!H:H,0) -> 0
A30: Lead_029 | B30: FILT_A | C30: 46202.491 | D30: 46202.495 | J30: =IF(D30="","",ROUND(24*MAX(0,(NETWORKDAYS.INTL(INT(C30),INT(D30),11)-1)*(TIME(18,30,0)-TIME(10,0,0))+IF(NETWORKDAYS.INTL(INT(D30),INT(D30),11),MEDIAN(MOD(D30,1),TIME(18,30,0),TIME(10,0,0)),TIME(18,30,0))-IF(NETWORKDAYS.INTL(INT(C30),INT(C30),11),MEDIAN(MOD(C30,1),TIME(18,30,0),TIME(10,0,0)),TIME(10,0,0))),4)) -> 0.1 | K30: {=IF(D30="","No Call",_xlfn.IFS(J30<=0.25,"<=15 min",J30<=0.5,"16-30 min",J30<=1,"31-60 min",TRUE,">60 min"))} -> <=15 min | L30: =_xlfn.XLOOKUP(A30,Lead_Data!A:A,Lead_Data!H:H,0) -> 0
A31: Lead_030 | B31: FILT_B | C31: 46193.361 | J31: =IF(D31="","",ROUND(24*MAX(0,(NETWORKDAYS.INTL(INT(C31),INT(D31),11)-1)*(TIME(18,30,0)-TIME(10,0,0))+IF(NETWORKDAYS.INTL(INT(D31),INT(D31),11),MEDIAN(MOD(D31,1),TIME(18,30,0),TIME(10,0,0)),TIME(18,30,0))-IF(NETWORKDAYS.INTL(INT(C31),INT(C31),11),MEDIAN(MOD(C31,1),TIME(18,30,0),TIME(10,0,0)),TIME(10,0,0))),4)) | K31: {=IF(D31="","No Call",_xlfn.IFS(J31<=0.25,"<=15 min",J31<=0.5,"16-30 min",J31<=1,"31-60 min",TRUE,">60 min"))} -> No Call | L31: =_xlfn.XLOOKUP(A31,Lead_Data!A:A,Lead_Data!H:H,0) -> 0
A32: Lead_031 | B32: FILT_B | C32: 46193.469 | D32: 46193.514 | E32: 46194.055 | F32: 46193.889 | G32: 46195.014 | J32: =IF(D32="","",ROUND(24*MAX(0,(NETWORKDAYS.INTL(INT(C32),INT(D32),11)-1)*(TIME(18,30,0)-TIME(10,0,0))+IF(NETWORKDAYS.INTL(INT(D32),INT(D32),11),MEDIAN(MOD(D32,1),TIME(18,30,0),TIME(10,0,0)),TIME(18,30,0))-IF(NETWORKDAYS.INTL(INT(C32),INT(C32),11),MEDIAN(MOD(C32,1),TIME(18,30,0),TIME(10,0,0)),TIME(10,0,0))),4)) -> 1.0667 | K32: {=IF(D32="","No Call",_xlfn.IFS(J32<=0.25,"<=15 min",J32<=0.5,"16-30 min",J32<=1,"31-60 min",TRUE,">60 min"))} -> >60 min | L32: =_xlfn.XLOOKUP(A32,Lead_Data!A:A,Lead_Data!H:H,0) -> 0
A33: Lead_032 | B33: FILT_A | C33: 46190.512 | D33: 46190.515 | E33: 46191.39 | F33: 46190.557 | G33: 46191.765 | J33: =IF(D33="","",ROUND(24*MAX(0,(NETWORKDAYS.INTL(INT(C33),INT(D33),11)-1)*(TIME(18,30,0)-TIME(10,0,0))+IF(NETWORKDAYS.INTL(INT(D33),INT(D33),11),MEDIAN(MOD(D33,1),TIME(18,30,0),TIME(10,0,0)),TIME(18,30,0))-IF(NETWORKDAYS.INTL(INT(C33),INT(C33),11),MEDIAN(MOD(C33,1),TIME(18,30,0),TIME(10,0,0)),TIME(10,0,0))),4)) -> 0.0833 | K33: {=IF(D33="","No Call",_xlfn.IFS(J33<=0.25,"<=15 min",J33<=0.5,"16-30 min",J33<=1,"31-60 min",TRUE,">60 min"))} -> <=15 min | L33: =_xlfn.XLOOKUP(A33,Lead_Data!A:A,Lead_Data!H:H,0) -> 0
A34: Lead_033 | B34: FILT_A | C34: 46206.587 | D34: 46206.595 | J34: =IF(D34="","",ROUND(24*MAX(0,(NETWORKDAYS.INTL(INT(C34),INT(D34),11)-1)*(TIME(18,30,0)-TIME(10,0,0))+IF(NETWORKDAYS.INTL(INT(D34),INT(D34),11),MEDIAN(MOD(D34,1),TIME(18,30,0),TIME(10,0,0)),TIME(18,30,0))-IF(NETWORKDAYS.INTL(INT(C34),INT(C34),11),MEDIAN(MOD(C34,1),TIME(18,30,0),TIME(10,0,0)),TIME(10,0,0))),4)) -> 0.1833 | K34: {=IF(D34="","No Call",_xlfn.IFS(J34<=0.25,"<=15 min",J34<=0.5,"16-30 min",J34<=1,"31-60 min",TRUE,">60 min"))} -> <=15 min | L34: =_xlfn.XLOOKUP(A34,Lead_Data!A:A,Lead_Data!H:H,0) -> 0
A35: Lead_034 | B35: FILT_F | C35: 46200.669 | D35: 46200.68 | E35: 46201.721 | J35: =IF(D35="","",ROUND(24*MAX(0,(NETWORKDAYS.INTL(INT(C35),INT(D35),11)-1)*(TIME(18,30,0)-TIME(10,0,0))+IF(NETWORKDAYS.INTL(INT(D35),INT(D35),11),MEDIAN(MOD(D35,1),TIME(18,30,0),TIME(10,0,0)),TIME(18,30,0))-IF(NETWORKDAYS.INTL(INT(C35),INT(C35),11),MEDIAN(MOD(C35,1),TIME(18,30,0),TIME(10,0,0)),TIME(10,0,0))),4)) -> 0.25 | K35: {=IF(D35="","No Call",_xlfn.IFS(J35<=0.25,"<=15 min",J35<=0.5,"16-30 min",J35<=1,"31-60 min",TRUE,">60 min"))} -> <=15 min | L35: =_xlfn.XLOOKUP(A35,Lead_Data!A:A,Lead_Data!H:H,0) -> 0
A36: Lead_035 | B36: SALES_B | C36: 46182.768 | D36: 46183.44 | E36: 46184.023 | F36: 46183.857 | G36: 46185.065 | J36: =IF(D36="","",ROUND(24*MAX(0,(NETWORKDAYS.INTL(INT(C36),INT(D36),11)-1)*(TIME(18,30,0)-TIME(10,0,0))+IF(NETWORKDAYS.INTL(INT(D36),INT(D36),11),MEDIAN(MOD(D36,1),TIME(18,30,0),TIME(10,0,0)),TIME(18,30,0))-IF(NETWORKDAYS.INTL(INT(C36),INT(C36),11),MEDIAN(MOD(C36,1),TIME(18,30,0),TIME(10,0,0)),TIME(10,0,0))),4)) -> 0.6333 | K36: {=IF(D36="","No Call",_xlfn.IFS(J36<=0.25,"<=15 min",J36<=0.5,"16-30 min",J36<=1,"31-60 min",TRUE,">60 min"))} -> 31-60 min | L36: =_xlfn.XLOOKUP(A36,Lead_Data!A:A,Lead_Data!H:H,0) -> 0
A37: Lead_036 | B37: FILT_C | C37: 46205.59 | D37: 46205.598 | J37: =IF(D37="","",ROUND(24*MAX(0,(NETWORKDAYS.INTL(INT(C37),INT(D37),11)-1)*(TIME(18,30,0)-TIME(10,0,0))+IF(NETWORKDAYS.INTL(INT(D37),INT(D37),11),MEDIAN(MOD(D37,1),TIME(18,30,0),TIME(10,0,0)),TIME(18,30,0))-IF(NETWORKDAYS.INTL(INT(C37),INT(C37),11),MEDIAN(MOD(C37,1),TIME(18,30,0),TIME(10,0,0)),TIME(10,0,0))),4)) -> 0.1833 | K37: {=IF(D37="","No Call",_xlfn.IFS(J37<=0.25,"<=15 min",J37<=0.5,"16-30 min",J37<=1,"31-60 min",TRUE,">60 min"))} -> <=15 min | L37: =_xlfn.XLOOKUP(A37,Lead_Data!A:A,Lead_Data!H:H,0) -> 0
A38: Lead_037 | B38: OTHER_1 | C38: 46188.366 | D38: 46188.453 | E38: 46189.203 | J38: =IF(D38="","",ROUND(24*MAX(0,(NETWORKDAYS.INTL(INT(C38),INT(D38),11)-1)*(TIME(18,30,0)-TIME(10,0,0))+IF(NETWORKDAYS.INTL(INT(D38),INT(D38),11),MEDIAN(MOD(D38,1),TIME(18,30,0),TIME(10,0,0)),TIME(18,30,0))-IF(NETWORKDAYS.INTL(INT(C38),INT(C38),11),MEDIAN(MOD(C38,1),TIME(18,30,0),TIME(10,0,0)),TIME(10,0,0))),4)) -> 0.8835 | K38: {=IF(D38="","No Call",_xlfn.IFS(J38<=0.25,"<=15 min",J38<=0.5,"16-30 min",J38<=1,"31-60 min",TRUE,">60 min"))} -> 31-60 min | L38: =_xlfn.XLOOKUP(A38,Lead_Data!A:A,Lead_Data!H:H,0) -> 0
A39: Lead_038 | B39: FILT_B | C39: 46182.482 | D39: 46182.503 | J39: =IF(D39="","",ROUND(24*MAX(0,(NETWORKDAYS.INTL(INT(C39),INT(D39),11)-1)*(TIME(18,30,0)-TIME(10,0,0))+IF(NETWORKDAYS.INTL(INT(D39),INT(D39),11),MEDIAN(MOD(D39,1),TIME(18,30,0),TIME(10,0,0)),TIME(18,30,0))-IF(NETWORKDAYS.INTL(INT(C39),INT(C39),11),MEDIAN(MOD(C39,1),TIME(18,30,0),TIME(10,0,0)),TIME(10,0,0))),4)) -> 0.5167 | K39: {=IF(D39="","No Call",_xlfn.IFS(J39<=0.25,"<=15 min",J39<=0.5,"16-30 min",J39<=1,"31-60 min",TRUE,">60 min"))} -> 31-60 min | L39: =_xlfn.XLOOKUP(A39,Lead_Data!A:A,Lead_Data!H:H,0) -> 0
A40: Lead_039 | B40: FILT_C | C40: 46209.618 | D40: 46209.619 | E40: 46210.411 | F40: 46210.244 | G40: 46210.452 | J40: =IF(D40="","",ROUND(24*MAX(0,(NETWORKDAYS.INTL(INT(C40),INT(D40),11)-1)*(TIME(18,30,0)-TIME(10,0,0))+IF(NETWORKDAYS.INTL(INT(D40),INT(D40),11),MEDIAN(MOD(D40,1),TIME(18,30,0),TIME(10,0,0)),TIME(18,30,0))-IF(NETWORKDAYS.INTL(INT(C40),INT(C40),11),MEDIAN(MOD(C40,1),TIME(18,30,0),TIME(10,0,0)),TIME(10,0,0))),4)) -> 0.0167 | K40: {=IF(D40="","No Call",_xlfn.IFS(J40<=0.25,"<=15 min",J40<=0.5,"16-30 min",J40<=1,"31-60 min",TRUE,">60 min"))} -> <=15 min | L40: =_xlfn.XLOOKUP(A40,Lead_Data!A:A,Lead_Data!H:H,0) -> 0
...

Sheet Call_Log
A1: Start Time | B1: Agent | C1: Call Type | D1: Duration (seconds) | E1: Disposition | F1: Call Time Slot | G1: Connected Flag
A2: 46203.378 | B2: FILT_G | C2: OUTBOUND | D2: 202 | E2: ANSWER | F2: =IF(MOD(A2,1)<TIME(12,0,0),"Before 12:00",IF(MOD(A2,1)<TIME(15,0,0),"12:00-15:00",IF(MOD(A2,1)<TIME(18,0,0),"15:00-18:00","After 18:00"))) -> Before 12:00 | G2: =--(E2="ANSWER") -> 1
A3: 46204.031 | B3: FILT_E | C3: OUTBOUND | D3: 14 | E3: BUSY | F3: =IF(MOD(A3,1)<TIME(12,0,0),"Before 12:00",IF(MOD(A3,1)<TIME(15,0,0),"12:00-15:00",IF(MOD(A3,1)<TIME(18,0,0),"15:00-18:00","After 18:00"))) -> Before 12:00 | G3: =--(E3="ANSWER") -> 0
A4: 46204.153 | B4: FILT_B | C4: OUTBOUND | D4: 0 | E4: FAILED | F4: =IF(MOD(A4,1)<TIME(12,0,0),"Before 12:00",IF(MOD(A4,1)<TIME(15,0,0),"12:00-15:00",IF(MOD(A4,1)<TIME(18,0,0),"15:00-18:00","After 18:00"))) -> Before 12:00 | G4: =--(E4="ANSWER") -> 0
A5: 46204.18 | B5: FILT_A | C5: OUTBOUND | D5: 2 | E5: FAILED | F5: =IF(MOD(A5,1)<TIME(12,0,0),"Before 12:00",IF(MOD(A5,1)<TIME(15,0,0),"12:00-15:00",IF(MOD(A5,1)<TIME(18,0,0),"15:00-18:00","After 18:00"))) -> Before 12:00 | G5: =--(E5="ANSWER") -> 0
A6: 46204.356 | B6: SALES_C | C6: OUTBOUND | D6: 208 | E6: ANSWER | F6: =IF(MOD(A6,1)<TIME(12,0,0),"Before 12:00",IF(MOD(A6,1)<TIME(15,0,0),"12:00-15:00",IF(MOD(A6,1)<TIME(18,0,0),"15:00-18:00","After 18:00"))) -> Before 12:00 | G6: =--(E6="ANSWER") -> 1
A7: 46204.447 | B7: FILT_D | C7: INBOUND | D7: 133 | E7: ANSWER | F7: =IF(MOD(A7,1)<TIME(12,0,0),"Before 12:00",IF(MOD(A7,1)<TIME(15,0,0),"12:00-15:00",IF(MOD(A7,1)<TIME(18,0,0),"15:00-18:00","After 18:00"))) -> Before 12:00 | G7: =--(E7="ANSWER") -> 1
A8: 46204.45 | B8: FILT_B | C8: OUTBOUND | D8: 9 | E8: NOANSWER | F8: =IF(MOD(A8,1)<TIME(12,0,0),"Before 12:00",IF(MOD(A8,1)<TIME(15,0,0),"12:00-15:00",IF(MOD(A8,1)<TIME(18,0,0),"15:00-18:00","After 18:00"))) -> Before 12:00 | G8: =--(E8="ANSWER") -> 0
A9: 46204.488 | B9: FILT_C | C9: INBOUND | D9: 14 | E9: BUSY | F9: =IF(MOD(A9,1)<TIME(12,0,0),"Before 12:00",IF(MOD(A9,1)<TIME(15,0,0),"12:00-15:00",IF(MOD(A9,1)<TIME(18,0,0),"15:00-18:00","After 18:00"))) -> Before 12:00 | G9: =--(E9="ANSWER") -> 0
A10: 46205.243 | B10: FILT_C | C10: OUTBOUND | D10: 8 | E10: NOANSWER | F10: =IF(MOD(A10,1)<TIME(12,0,0),"Before 12:00",IF(MOD(A10,1)<TIME(15,0,0),"12:00-15:00",IF(MOD(A10,1)<TIME(18,0,0),"15:00-18:00","After 18:00"))) -> Before 12:00 | G10: =--(E10="ANSWER") -> 0
A11: 46205.417 | B11: FILT_A | C11: INBOUND | D11: 21 | E11: NOANSWER | F11: =IF(MOD(A11,1)<TIME(12,0,0),"Before 12:00",IF(MOD(A11,1)<TIME(15,0,0),"12:00-15:00",IF(MOD(A11,1)<TIME(18,0,0),"15:00-18:00","After 18:00"))) -> Before 12:00 | G11: =--(E11="ANSWER") -> 0
A12: 46205.419 | B12: SALES_B | C12: INBOUND | D12: 4 | E12: FAILED | F12: =IF(MOD(A12,1)<TIME(12,0,0),"Before 12:00",IF(MOD(A12,1)<TIME(15,0,0),"12:00-15:00",IF(MOD(A12,1)<TIME(18,0,0),"15:00-18:00","After 18:00"))) -> Before 12:00 | G12: =--(E12="ANSWER") -> 0
A13: 46205.425 | B13: FILT_D | C13: OUTBOUND | D13: 99 | E13: ANSWER | F13: =IF(MOD(A13,1)<TIME(12,0,0),"Before 12:00",IF(MOD(A13,1)<TIME(15,0,0),"12:00-15:00",IF(MOD(A13,1)<TIME(18,0,0),"15:00-18:00","After 18:00"))) -> Before 12:00 | G13: =--(E13="ANSWER") -> 1
... A101: 46210.964 | B101: SALES_E | C101: OUTBOUND | D101: 22 | E101: NOANSWER | F101: =IF(MOD(A101,1)<TIME(12,0,0),"Before 12:00",IF(MOD(A101,1)<TIME(15,0,0),"12:00-15:00",IF(MOD(A101,1)<TIME(18,0,0),"15:00-18:00","After 18:00"))) -> After 18:00 | G101: =--(E101="ANSWER") -> 0

Sheet ReadMe
A1: Item | B1: Definition / Approach
A2: Analysis window | B2: Lead_Data contains 100 leads created in the last 30 days; Call_Log contains 100 calls from the last 7 days.
A3: Conversion | B3: First Shipment Booked Date is populated OR Contact Stage is Verified / Service Done.
A4: Working-hour TAT | B4: Monday-Saturday, 10:00-18:30; Sundays excluded. Calculated from Created On to First Phone Call.
A5: Funnel interpretation | B5: Contact Stage is a current-state distribution, not a strict sequential event funnel. The largest current blockage is therefore identified by the stage with the most leads.
A6: Agent caveat | B6: Current Owner cannot be used for a fair individual conversion ranking because 15 of 16 converted leads are still assigned to Filteration owners.
A7: Sample caveat | B7: Findings are directional: 100 leads and 7 days of call logs. Validate actions on the next cohort before permanent budget changes.

Sheet Task-1 Funnel
A1: Task 1 - Funnel Drop-off
A4: Column1 | B4: Lead Count | C4: % of Leads
A5: Not Connected | B5: 16 | C5: =B5/COUNTA(Lead_Data!$A$2:$A$101) -> 0.16
A6: Verified | B6: 13 | C6: =B6/COUNTA(Lead_Data!$A$2:$A$101) -> 0.13
A7: Junk | B7: 8 | C7: =B7/COUNTA(Lead_Data!$A$2:$A$101) -> 0.08
A8: Not Interested | B8: 7 | C8: =B8/COUNTA(Lead_Data!$A$2:$A$101) -> 0.07
A9: Follow-up in Future | B9: 7 | C9: =B9/COUNTA(Lead_Data!$A$2:$A$101) -> 0.07
A10: Not Eligible Yet | B10: 7 | C10: =B10/COUNTA(Lead_Data!$A$2:$A$101) -> 0.07
A11: Call Back | B11: 6 | C11: =B11/COUNTA(Lead_Data!$A$2:$A$101) -> 0.06
A12: Uncontactable | B12: 5 | C12: =B12/COUNTA(Lead_Data!$A$2:$A$101) -> 0.05
A13: Follow Up | B13: 5 | C13: =B13/COUNTA(Lead_Data!$A$2:$A$101) -> 0.05
A14: Verification Pending | B14: 4 | C14: =B14/COUNTA(Lead_Data!$A$2:$A$101) -> 0.04
A15: New Lead | B15: 4 | C15: =B15/COUNTA(Lead_Data!$A$2:$A$101) -> 0.04
A16: Offer Pitched | B16: 4 | C16: =B16/COUNTA(Lead_Data!$A$2:$A$101) -> 0.04
... A21: Interested | B21: 2 | C21: =B21/COUNTA(Lead_Data!$A$2:$A$101) -> 0.02
A23: Key Finding | B23: Value | C23: Interpretation
A24: Biggest current blockage | B24: Not Connected | C24: 16 Leads (16%) are stuck here, highest of any atage.
A25: Likely driver | B25: Contactability | C25: Another 5 leads are uncontactable, taking contactibility related blockage by 21%.
A26: Opinion | B26: Current-state funnel | C26: Stage counts show where leads sit now, they do not prove exact sequential drop-off without full stage-history events.

Sheet Task-2 Segmentation
A1: Task 2 - Segmentation Analysis
A4: A. Marketing Performance by Lead Source | F4: C. Call Connectivity Analysis
A5: Lead Source | B5: Tota Leads | C5: Converted Leads | D5: Conversion rate | F5: Row Labels | G5: Calls | H5: Share
A6: Organic | B6: 41 | C6: 12 | D6: 0.29268293 | F6: ANSWER | G6: =COUNTIF(Call_Log!$E$2:$E$101,F6) -> 60 | H6: =G6/COUNTA(Call_Log!$E$2:$E$101) -> 0.6
A7: App | B7: 12 | C7: 2 | D7: 0.16666667 | F7: BUSY | G7: =COUNTIF(Call_Log!$E$2:$E$101,F7) -> 10 | H7: =G7/COUNTA(Call_Log!$E$2:$E$101) -> 0.1
A8: Google Paid | B8: 30 | C8: 2 | D8: 0.066666667 | F8: CANCEL | G8: =COUNTIF(Call_Log!$E$2:$E$101,F8) -> 3 | H8: =G8/COUNTA(Call_Log!$E$2:$E$101) -> 0.03
A9: Meta | B9: 12 | C9: 0 | D9: 0 | F9: FAILED | G9: =COUNTIF(Call_Log!$E$2:$E$101,F9) -> 4 | H9: =G9/COUNTA(Call_Log!$E$2:$E$101) -> 0.04
A10: Facebook | B10: 5 | C10: 0 | D10: 0 | F10: NOANSWER | G10: =COUNTIF(Call_Log!$E$2:$E$101,F10) -> 23 | H10: =G10/COUNTA(Call_Log!$E$2:$E$101) -> 0.23
A12: Insight | F12: Metric | G12: Value | H12: Interpretation
A13: Organic is the top-performing source, generating 12 conversions from 41 leads (29.3%). Meta and Facebook generated 17 leads with zero conversions, while Google Paid converted only 6.7%, suggesting a need to review paid campaign targeting and lead quality. | F13: Failed to connect | G13: =1-H6 -> 0.4 | H13: NOANSWER + BUSY + FAILED + CANCEL
F15: Insight: 40% of call attempts failed to connect, mainly due to no-answer cases (24%). The team should optimise calling schedules and follow-up attempts to improve lead reachability.
A16: B. Merchant Size vs Conversion
A17: Monthly Order Volume | B17: Leads | C17: Conversion rate
A18: Just starting out | B18: 28 | C18: =SUMIF(Lead_Data!$G$2:$G$101,'Task-2 Segmentation'!A18,Lead_Data!$H$2:$H$101)/B18 -> 0.10714286
A19: 1-100 | B19: 28 | C19: =SUMIF(Lead_Data!$G$2:$G$101,'Task-2 Segmentation'!A19,Lead_Data!$H$2:$H$101)/B19 -> 0.14285714
A20: 100-300 | B20: 23 | C20: =SUMIF(Lead_Data!$G$2:$G$101,'Task-2 Segmentation'!A20,Lead_Data!$H$2:$H$101)/B20 -> 0.17391304
A21: 500+ | B21: 11 | C21: =SUMIF(Lead_Data!$G$2:$G$101,'Task-2 Segmentation'!A21,Lead_Data!$H$2:$H$101)/B21 -> 0.27272727
A22: 300-500 | B22: 10 | C22: =SUMIF(Lead_Data!$G$2:$G$101,'Task-2 Segmentation'!A22,Lead_Data!$H$2:$H$101)/B22 -> 0.2
A24: Insight
A25: Yes, there is a positive correlation. Conversion rises steadily with merchant size, from 10.7% for 'Just starting out' to 27.3% for 500+. Prioritise 300+ volume leads, while preserving enough coverage for the larger 100-300 lead pool.

Sheet Additional Insights
A1: Task 3 - Additional Insights
A4: Insight 1 - Speed to Lead | F4: Diagnostic - Connection Rate by Call Time
A5: First Response Bucket | B5: Leads | C5: Converted | D5: Conversion Rate | F5: Row Labels | G5: Count of Disposition | H5: Sum of Connected Flag | I5: Answer Rate
A6: <=15 min | B6: 44 | C6: 10 | D6: 0.22727273 | F6: Before 12:00 | G6: 30 | H6: 15 | I6: =H6/G6 -> 0.5
A7: 16-30 min | B7: 34 | C7: 4 | D7: 0.11764706 | F7: 12:00-15:00 | G7: 32 | H7: 27 | I7: =H7/G7 -> 0.84375
A8: 31-60 min | B8: 17 | C8: 2 | D8: 0.11764706 | F8: 15:00-18:00 | G8: 21 | H8: 11 | I8: =H8/G8 -> 0.52380952
A9: >60 min | B9: 4 | C9: 0 | D9: 0 | F9: After 18:00 | G9: 17 | H9: 7 | I9: =H9/G9 -> 0.41176471
A10: No Call | B10: 1 | C10: 0 | D10: 0
A12: Analysed: Leads contacted within 15 minutes converted at 22.7% (10/44), compared with 9.5% (2/21) for leads contacted after 30 minutes. This indicates that improving first-response speed could directly improve conversion rates. | F12: 12:00-15:00 has the strongest observed answer rate at 84.4% (27/32). Use this window for priority retries, then validate over a larger sample.
A16: Insight 2 - Handoff / Ownership Control
A17: Owner Team | B17: Converted Leads | C17: Conversion rate
A18: Filteration | B18: 15 | C18: =B18/SUM($B$18:$B$20) -> 0.9375
A19: Sales | B19: 1 | C19: =B19/SUM($B$18:$B$20) -> 0.0625
A20: Other / historical | B20: 0 | C20: =B20/SUM($B$18:$B$20) -> 0
A22: Metric | B22: Count | C22: Rate | D22: Operational Meaning
A23: Converted Leads | B23: =SUM(Lead_Data!$H$2:$H$101) -> 16 | C23: =B23/$B$23 -> 1 | D23: All leads meeting the stated conversion definition
A24: Converted leads owned by Sales | B24: =COUNTIFS(Lead_Data!$H$2:$H$101,1,Lead_Data!$I$2:$I$101,"Sales") -> 1 | C24: =B24/$B$23 -> 0.0625 | D24: Handoff appears completed
A25: Converted leads not owned by Sales | B25: =COUNTIFS(Lead_Data!$H$2:$H$101,1,Lead_Data!$I$2:$I$101,"<>Sales") -> 15 | C25: =B25/$B$23 -> 0.9375 | D25: Handoff missed or Owner field not updated
A27: Analysed: 93.8% of converted leads are still assigned to Filteration owners, indicating a potential gap in Sales handoff tracking or CRM ownership updates.

Sheet Executive Summary
A1: 30-Day Lead Funnel & Efficiency Summary
A4: Total Leads | D4: Conversions | G4: Conversion rate | J4: Failed Connection Rate
A5: =COUNTA(Lead_Data!A2:A101) -> 100 | D5: =SUM(Lead_Data!H2:H101) -> 16 | G5: =D5/A5 -> 0.16 | J5: ='Task-2 Segmentation'!G13 -> 0.4
A9: Key Findings
A10: 1 | B10: Funnel Blockage | C10: Not Connected is the largest pipeline blockage with 16 leads. Including Uncontactable leads, 21 leads have a contactability issue, indicating a need to improve lead reachability.
A11: 2 | B11: Marketing Efficiency | C11: Organic converts at 29.3% (12/41). Meta + Facebook deliver 0/17, while Google Paid converts 2/30 (6.7%).
A12: 3 | B12: Merchant Quality | C12: Conversion increases with merchant size, reaching 27.3% for 500+ and 20.0% for 300-500.
A13: 4 | B13: Speed to Lead | C13: Leads contacted within 15 minutes convert at 22.7%, more than double the 9.5% conversion rate observed after 30 minutes.
A14: 5 | B14: Process Control | C14: 15 of 16 converted leads remain outside Sales ownership, indicating a potential handoff tracking or CRM ownership update issue.
A17: Prioritised Actions for Next Week
A18: Priority | B18: Action | C18: Owner / Due | D18: Success Measure | G18: Owner | J18: Success Measure
A19: 1 | B19: Audit and reassign the 15 converted Filteration-owned leads, activate stage-based routing and a daily ownership exception report. | C19: Sales Ops | Tuesday | D19: 100% of Verified / Service Done leads owned by Sales | G19: Sales Ops | J19: 100% of Verified / Service Done leads owned by Sales
A20: 2 | B20: Test 12:00-15:00 as a priority retry window based on the observed 84.4% answer rate. | C20: Filteration Lead | Wednesday | D20: >=90% of new leads called within 15 minutes; non-connect below 35% | G20: Filteration Lead | J20: >=90% of new leads called within 15 minutes; non-connect below 35%
A21: 3 | B21: Review paid targeting and lead quality: analyse Meta/Facebook audience quality, optimise Google Paid campaigns, and prioritise 300+ volume leads. | C21: Marketing + Sales | Friday | D21: Paid conversion above 10% in the next controlled cohort | G21: Marketing + Sales | J21: Paid conversion above 10% in the next controlled cohort
